2023-04-27 11:23:28 INFO Logging initialized. Log file: ./logs/fastapi.log,startup fastapi
2023-04-27 11:23:49 INFO Logging initialized. Log file: ./logs/fastapi.log,startup fastapi
2023-04-27 11:23:59 INFO Logging initialized. Log file: ./logs/fastapi.log,startup fastapi
2023-04-27 15:17:55 INFO Logging initialized. Log file: ./logs/fastapi.log,startup fastapi
2023-04-27 15:49:30 INFO Logging initialized. Log file: ./logs/fastapi.log,startup fastapi
2023-04-27 15:50:13 INFO Logging initialized. Log file: ./logs/fastapi.log,startup fastapi
2023-05-07 23:21:22 INFO Logging initialized. Log file: ./logs/fastapi.log,startup fastapi
2023-05-08 22:04:55 INFO Logging initialized. Log file: ./logs/fastapi.log,startup fastapi
2023-05-08 22:05:32 INFO Logging initialized. Log file: ./logs/fastapi.log,startup fastapi
2023-05-08 22:05:39 INFO Logging initialized. Log file: ./logs/fastapi.log,startup fastapi
2023-05-08 22:05:53 INFO Logging initialized. Log file: ./logs/fastapi.log,startup fastapi
2023-05-08 22:06:11 INFO Logging initialized. Log file: ./logs/fastapi.log,startup fastapi
2023-05-08 22:10:30 INFO Logging initialized. Log file: ./logs/fastapi.log,startup fastapi
2023-05-08 23:45:20 INFO Logging initialized. Log file: /Users/lijianxing/lijx-devops/python/fastapi/op-kube-manage-api/logs/fastapi.log,(pymysql.err.OperationalError) (2003, "Can't connect to MySQL server on 'ops-kube_manage-mysql' ([Errno 8] nodename nor servname provided, or not known)")
(Background on this error at: https://sqlalche.me/e/14/e3q8)
2023-05-08 23:45:22 INFO Logging initialized. Log file: /Users/lijianxing/lijx-devops/python/fastapi/op-kube-manage-api/logs/fastapi.log,(pymysql.err.OperationalError) (2003, "Can't connect to MySQL server on 'ops-kube_manage-mysql' ([Errno 8] nodename nor servname provided, or not known)")
(Background on this error at: https://sqlalche.me/e/14/e3q8)
2023-05-08 23:45:22 INFO Logging initialized. Log file: /Users/lijianxing/lijx-devops/python/fastapi/op-kube-manage-api/logs/fastapi.log,(pymysql.err.OperationalError) (2003, "Can't connect to MySQL server on 'ops-kube_manage-mysql' ([Errno 8] nodename nor servname provided, or not known)")
(Background on this error at: https://sqlalche.me/e/14/e3q8)
2023-05-08 23:45:22 INFO Logging initialized. Log file: /Users/lijianxing/lijx-devops/python/fastapi/op-kube-manage-api/logs/fastapi.log,(pymysql.err.OperationalError) (2003, "Can't connect to MySQL server on 'ops-kube_manage-mysql' ([Errno 8] nodename nor servname provided, or not known)")
(Background on this error at: https://sqlalche.me/e/14/e3q8)
2023-05-08 23:45:22 INFO Logging initialized. Log file: /Users/lijianxing/lijx-devops/python/fastapi/op-kube-manage-api/logs/fastapi.log,(pymysql.err.OperationalError) (2003, "Can't connect to MySQL server on 'ops-kube_manage-mysql' ([Errno 8] nodename nor servname provided, or not known)")
(Background on this error at: https://sqlalche.me/e/14/e3q8)
2023-05-08 23:45:23 INFO Logging initialized. Log file: /Users/lijianxing/lijx-devops/python/fastapi/op-kube-manage-api/logs/fastapi.log,(pymysql.err.OperationalError) (2003, "Can't connect to MySQL server on 'ops-kube_manage-mysql' ([Errno 8] nodename nor servname provided, or not known)")
(Background on this error at: https://sqlalche.me/e/14/e3q8)
2023-05-08 23:45:23 INFO Logging initialized. Log file: /Users/lijianxing/lijx-devops/python/fastapi/op-kube-manage-api/logs/fastapi.log,(pymysql.err.OperationalError) (2003, "Can't connect to MySQL server on 'ops-kube_manage-mysql' ([Errno 8] nodename nor servname provided, or not known)")
(Background on this error at: https://sqlalche.me/e/14/e3q8)
2023-05-08 23:45:23 INFO Logging initialized. Log file: /Users/lijianxing/lijx-devops/python/fastapi/op-kube-manage-api/logs/fastapi.log,(pymysql.err.OperationalError) (2003, "Can't connect to MySQL server on 'ops-kube_manage-mysql' ([Errno 8] nodename nor servname provided, or not known)")
(Background on this error at: https://sqlalche.me/e/14/e3q8)
2023-05-08 23:45:23 INFO Logging initialized. Log file: /Users/lijianxing/lijx-devops/python/fastapi/op-kube-manage-api/logs/fastapi.log,(pymysql.err.OperationalError) (2003, "Can't connect to MySQL server on 'ops-kube_manage-mysql' ([Errno 8] nodename nor servname provided, or not known)")
(Background on this error at: https://sqlalche.me/e/14/e3q8)
2023-05-08 23:45:24 INFO Logging initialized. Log file: /Users/lijianxing/lijx-devops/python/fastapi/op-kube-manage-api/logs/fastapi.log,(pymysql.err.OperationalError) (2003, "Can't connect to MySQL server on 'ops-kube_manage-mysql' ([Errno 8] nodename nor servname provided, or not known)")
(Background on this error at: https://sqlalche.me/e/14/e3q8)
2023-05-08 23:45:24 INFO Logging initialized. Log file: /Users/lijianxing/lijx-devops/python/fastapi/op-kube-manage-api/logs/fastapi.log,(pymysql.err.OperationalError) (2003, "Can't connect to MySQL server on 'ops-kube_manage-mysql' ([Errno 8] nodename nor servname provided, or not known)")
(Background on this error at: https://sqlalche.me/e/14/e3q8)
2023-05-08 23:45:24 INFO Logging initialized. Log file: /Users/lijianxing/lijx-devops/python/fastapi/op-kube-manage-api/logs/fastapi.log,(pymysql.err.OperationalError) (2003, "Can't connect to MySQL server on 'ops-kube_manage-mysql' ([Errno 8] nodename nor servname provided, or not known)")
(Background on this error at: https://sqlalche.me/e/14/e3q8)
2023-05-08 23:45:24 INFO Logging initialized. Log file: /Users/lijianxing/lijx-devops/python/fastapi/op-kube-manage-api/logs/fastapi.log,(pymysql.err.OperationalError) (2003, "Can't connect to MySQL server on 'ops-kube_manage-mysql' ([Errno 8] nodename nor servname provided, or not known)")
(Background on this error at: https://sqlalche.me/e/14/e3q8)
2023-05-08 23:45:24 INFO Logging initialized. Log file: /Users/lijianxing/lijx-devops/python/fastapi/op-kube-manage-api/logs/fastapi.log,(pymysql.err.OperationalError) (2003, "Can't connect to MySQL server on 'ops-kube_manage-mysql' ([Errno 8] nodename nor servname provided, or not known)")
(Background on this error at: https://sqlalche.me/e/14/e3q8)
2023-05-08 23:45:24 INFO Logging initialized. Log file: /Users/lijianxing/lijx-devops/python/fastapi/op-kube-manage-api/logs/fastapi.log,(pymysql.err.OperationalError) (2003, "Can't connect to MySQL server on 'ops-kube_manage-mysql' ([Errno 8] nodename nor servname provided, or not known)")
(Background on this error at: https://sqlalche.me/e/14/e3q8)
2023-05-08 23:45:26 INFO Logging initialized. Log file: /Users/lijianxing/lijx-devops/python/fastapi/op-kube-manage-api/logs/fastapi.log,(pymysql.err.OperationalError) (2003, "Can't connect to MySQL server on 'ops-kube_manage-mysql' ([Errno 8] nodename nor servname provided, or not known)")
(Background on this error at: https://sqlalche.me/e/14/e3q8)
2023-05-08 23:45:26 INFO Logging initialized. Log file: /Users/lijianxing/lijx-devops/python/fastapi/op-kube-manage-api/logs/fastapi.log,(pymysql.err.OperationalError) (2003, "Can't connect to MySQL server on 'ops-kube_manage-mysql' ([Errno 8] nodename nor servname provided, or not known)")
(Background on this error at: https://sqlalche.me/e/14/e3q8)
2023-05-08 23:45:26 INFO Logging initialized. Log file: /Users/lijianxing/lijx-devops/python/fastapi/op-kube-manage-api/logs/fastapi.log,(pymysql.err.OperationalError) (2003, "Can't connect to MySQL server on 'ops-kube_manage-mysql' ([Errno 8] nodename nor servname provided, or not known)")
(Background on this error at: https://sqlalche.me/e/14/e3q8)
2023-05-08 23:45:26 INFO Logging initialized. Log file: /Users/lijianxing/lijx-devops/python/fastapi/op-kube-manage-api/logs/fastapi.log,(pymysql.err.OperationalError) (2003, "Can't connect to MySQL server on 'ops-kube_manage-mysql' ([Errno 8] nodename nor servname provided, or not known)")
(Background on this error at: https://sqlalche.me/e/14/e3q8)
2023-05-08 23:45:28 INFO Logging initialized. Log file: /Users/lijianxing/lijx-devops/python/fastapi/op-kube-manage-api/logs/fastapi.log,(pymysql.err.OperationalError) (2003, "Can't connect to MySQL server on 'ops-kube_manage-mysql' ([Errno 8] nodename nor servname provided, or not known)")
(Background on this error at: https://sqlalche.me/e/14/e3q8)
2023-05-08 23:45:28 INFO Logging initialized. Log file: /Users/lijianxing/lijx-devops/python/fastapi/op-kube-manage-api/logs/fastapi.log,(pymysql.err.OperationalError) (2003, "Can't connect to MySQL server on 'ops-kube_manage-mysql' ([Errno 8] nodename nor servname provided, or not known)")
(Background on this error at: https://sqlalche.me/e/14/e3q8)
2023-05-08 23:45:28 INFO Logging initialized. Log file: /Users/lijianxing/lijx-devops/python/fastapi/op-kube-manage-api/logs/fastapi.log,(pymysql.err.OperationalError) (2003, "Can't connect to MySQL server on 'ops-kube_manage-mysql' ([Errno 8] nodename nor servname provided, or not known)")
(Background on this error at: https://sqlalche.me/e/14/e3q8)
2023-05-08 23:45:28 INFO Logging initialized. Log file: /Users/lijianxing/lijx-devops/python/fastapi/op-kube-manage-api/logs/fastapi.log,(pymysql.err.OperationalError) (2003, "Can't connect to MySQL server on 'ops-kube_manage-mysql' ([Errno 8] nodename nor servname provided, or not known)")
(Background on this error at: https://sqlalche.me/e/14/e3q8)
2023-05-10 15:31:21 INFO Logging initialized. Log file: /Users/lijianxing/lijx-devops/python/fastapi/op-kube-manage-api/logs/fastapi.log,(pymysql.err.OperationalError) (2003, "Can't connect to MySQL server on 'ops-kube_manage-mysql' ([Errno 8] nodename nor servname provided, or not known)")
(Background on this error at: https://sqlalche.me/e/14/e3q8)
2023-05-10 15:32:31 INFO Logging initialized. Log file: /Users/lijianxing/lijx-devops/python/fastapi/op-kube-manage-api/logs/fastapi.log,(pymysql.err.OperationalError) (2003, "Can't connect to MySQL server on '127.0.0.1' ([Errno 61] Connection refused)")
(Background on this error at: https://sqlalche.me/e/14/e3q8)
2023-05-10 22:56:31 INFO Logging initialized. Log file: /Users/lijianxing/lijx-devops/python/fastapi/op-kube-manage-api/logs/fastapi.log,Failed to delete Pod  in namespace dev: 'PodManager' object has no attribute 'api'
2023-05-10 22:56:55 INFO Logging initialized. Log file: /Users/lijianxing/lijx-devops/python/fastapi/op-kube-manage-api/logs/fastapi.log,Failed to delete Pod  in namespace dev: 'PodManager' object has no attribute 'api'
2023-05-10 22:58:34 INFO Logging initialized. Log file: /Users/lijianxing/lijx-devops/python/fastapi/op-kube-manage-api/logs/fastapi.log,Failed to delete Pod  in namespace dev: 'PodManager' object has no attribute 'api'
2023-05-10 23:00:42 INFO Logging initialized. Log file: /Users/lijianxing/lijx-devops/python/fastapi/op-kube-manage-api/logs/fastapi.log,Failed to delete Pod  in namespace dev: 'AppsV1Api' object has no attribute 'list_namespaced_pod'
2023-05-10 23:00:54 INFO Logging initialized. Log file: /Users/lijianxing/lijx-devops/python/fastapi/op-kube-manage-api/logs/fastapi.log,Failed to delete Pod  in namespace dev: 'AppsV1Api' object has no attribute 'list_namespaced_pod'
2023-05-10 23:09:55 INFO Logging initialized. Log file: /Users/lijianxing/lijx-devops/python/fastapi/op-kube-manage-api/logs/fastapi.log,Failed to delete Pod  in namespace dev: 'V1PodStatus' object has no attribute 'ready'
2023-05-10 23:09:57 INFO Logging initialized. Log file: /Users/lijianxing/lijx-devops/python/fastapi/op-kube-manage-api/logs/fastapi.log,Failed to delete Pod  in namespace dev: 'V1PodStatus' object has no attribute 'ready'
2023-05-10 23:11:55 INFO Logging initialized. Log file: /Users/lijianxing/lijx-devops/python/fastapi/op-kube-manage-api/logs/fastapi.log,Failed to delete Pod  in namespace dev: 'V1PodStatus' object has no attribute 'ready'
2023-05-10 23:12:52 INFO Logging initialized. Log file: /Users/lijianxing/lijx-devops/python/fastapi/op-kube-manage-api/logs/fastapi.log,Failed to delete Pod  in namespace dev: name 'pod_ready' is not defined
2023-05-10 23:41:35 INFO Logging initialized. Log file: /Users/lijianxing/lijx-devops/python/fastapi/op-kube-manage-api/logs/fastapi.log,Failed to delete Pod  in namespace dev: 'V1PodSpec' object has no attribute 'name'
2023-05-10 23:43:12 INFO Logging initialized. Log file: /Users/lijianxing/lijx-devops/python/fastapi/op-kube-manage-api/logs/fastapi.log,Failed to delete Pod  in namespace dev: 'list' object has no attribute 'ports'
2023-05-10 23:43:27 INFO Logging initialized. Log file: /Users/lijianxing/lijx-devops/python/fastapi/op-kube-manage-api/logs/fastapi.log,Failed to delete Pod  in namespace dev: 'list' object has no attribute 'ports'
2023-05-10 23:53:40 INFO Logging initialized. Log file: /Users/lijianxing/lijx-devops/python/fastapi/op-kube-manage-api/logs/fastapi.log,Failed to delete Pod  in namespace dev: sequence item 0: expected str instance, int found
2023-05-11 00:17:49 INFO Logging initialized. Log file: /Users/lijianxing/lijx-devops/python/fastapi/op-kube-manage-api/logs/fastapi.log,Failed to delete Pod  in namespace dev: name 'pod_error_message' is not defined
2023-05-11 00:18:42 INFO Logging initialized. Log file: /Users/lijianxing/lijx-devops/python/fastapi/op-kube-manage-api/logs/fastapi.log,Failed to delete Pod  in namespace dev: unhashable type: 'list'
2023-05-11 00:27:44 INFO Logging initialized. Log file: /Users/lijianxing/lijx-devops/python/fastapi/op-kube-manage-api/logs/fastapi.log,Failed to delete Pod  in namespace dev: 'V1PodStatus' object has no attribute 'ready_replicas'
2023-05-11 00:29:54 INFO Logging initialized. Log file: /Users/lijianxing/lijx-devops/python/fastapi/op-kube-manage-api/logs/fastapi.log,Failed to delete Pod  in namespace dev: 'V1PodStatus' object has no attribute 'replicas'
2023-05-11 00:32:13 INFO Logging initialized. Log file: /Users/lijianxing/lijx-devops/python/fastapi/op-kube-manage-api/logs/fastapi.log,Failed to delete Pod  in namespace dev: 'V1PodSpec' object has no attribute 'replicas'
2023-05-11 00:32:15 INFO Logging initialized. Log file: /Users/lijianxing/lijx-devops/python/fastapi/op-kube-manage-api/logs/fastapi.log,Failed to delete Pod  in namespace dev: 'V1PodSpec' object has no attribute 'replicas'
2023-05-11 00:40:00 INFO Logging initialized. Log file: /Users/lijianxing/lijx-devops/python/fastapi/op-kube-manage-api/logs/fastapi.log,Failed to delete Pod  in namespace dev: 'V1PodSpec' object has no attribute 'replicas'
2023-05-11 00:40:50 INFO Logging initialized. Log file: /Users/lijianxing/lijx-devops/python/fastapi/op-kube-manage-api/logs/fastapi.log,Failed to delete Pod  in namespace dev: 'NoneType' object has no attribute 'replace'
2023-05-11 00:43:44 INFO Logging initialized. Log file: /Users/lijianxing/lijx-devops/python/fastapi/op-kube-manage-api/logs/fastapi.log,Failed to delete Pod  in namespace dev: 'V1PodSpec' object has no attribute 'replicas'
2023-05-11 00:43:45 INFO Logging initialized. Log file: /Users/lijianxing/lijx-devops/python/fastapi/op-kube-manage-api/logs/fastapi.log,Failed to delete Pod  in namespace dev: 'V1PodSpec' object has no attribute 'replicas'
2023-05-11 00:45:16 INFO Logging initialized. Log file: /Users/lijianxing/lijx-devops/python/fastapi/op-kube-manage-api/logs/fastapi.log,Failed to delete Pod  in namespace dev: 'NoneType' object has no attribute 'replace'
2023-05-11 00:45:55 INFO Logging initialized. Log file: /Users/lijianxing/lijx-devops/python/fastapi/op-kube-manage-api/logs/fastapi.log,Failed to delete Pod  in namespace dev: 'NoneType' object has no attribute 'replace'
2023-05-11 00:46:26 INFO Logging initialized. Log file: /Users/lijianxing/lijx-devops/python/fastapi/op-kube-manage-api/logs/fastapi.log,Failed to delete Pod  in namespace dev: 'NoneType' object has no attribute 'replace'
2023-05-11 00:47:11 INFO Logging initialized. Log file: /Users/lijianxing/lijx-devops/python/fastapi/op-kube-manage-api/logs/fastapi.log,Failed to delete Pod  in namespace dev: 'NoneType' object has no attribute 'replace'
2023-05-11 00:47:12 INFO Logging initialized. Log file: /Users/lijianxing/lijx-devops/python/fastapi/op-kube-manage-api/logs/fastapi.log,Failed to delete Pod  in namespace dev: 'NoneType' object has no attribute 'replace'
2023-05-11 00:47:13 INFO Logging initialized. Log file: /Users/lijianxing/lijx-devops/python/fastapi/op-kube-manage-api/logs/fastapi.log,Failed to delete Pod  in namespace dev: 'NoneType' object has no attribute 'replace'
2023-05-11 00:47:14 INFO Logging initialized. Log file: /Users/lijianxing/lijx-devops/python/fastapi/op-kube-manage-api/logs/fastapi.log,Failed to delete Pod  in namespace dev: 'NoneType' object has no attribute 'replace'
2023-05-11 00:47:15 INFO Logging initialized. Log file: /Users/lijianxing/lijx-devops/python/fastapi/op-kube-manage-api/logs/fastapi.log,Failed to delete Pod  in namespace dev: 'NoneType' object has no attribute 'replace'
2023-05-11 00:47:17 INFO Logging initialized. Log file: /Users/lijianxing/lijx-devops/python/fastapi/op-kube-manage-api/logs/fastapi.log,Failed to delete Pod  in namespace dev: 'NoneType' object has no attribute 'replace'
2023-05-11 00:47:20 INFO Logging initialized. Log file: /Users/lijianxing/lijx-devops/python/fastapi/op-kube-manage-api/logs/fastapi.log,Failed to delete Pod  in namespace dev: 'NoneType' object has no attribute 'replace'
2023-05-11 00:47:21 INFO Logging initialized. Log file: /Users/lijianxing/lijx-devops/python/fastapi/op-kube-manage-api/logs/fastapi.log,Failed to delete Pod  in namespace dev: 'NoneType' object has no attribute 'replace'
2023-05-11 00:49:31 INFO Logging initialized. Log file: /Users/lijianxing/lijx-devops/python/fastapi/op-kube-manage-api/logs/fastapi.log,Failed to delete Pod  in namespace dev: 'NoneType' object has no attribute 'replace'
2023-05-11 00:51:50 INFO Logging initialized. Log file: /Users/lijianxing/lijx-devops/python/fastapi/op-kube-manage-api/logs/fastapi.log,Failed to delete Pod  in namespace dev: 'datetime.datetime' object is not callable
2023-05-11 00:52:39 INFO Logging initialized. Log file: /Users/lijianxing/lijx-devops/python/fastapi/op-kube-manage-api/logs/fastapi.log,Failed to delete Pod  in namespace dev: 'datetime.datetime' object is not callable
2023-05-11 00:52:40 INFO Logging initialized. Log file: /Users/lijianxing/lijx-devops/python/fastapi/op-kube-manage-api/logs/fastapi.log,Failed to delete Pod  in namespace dev: 'datetime.datetime' object is not callable
2023-05-11 00:52:41 INFO Logging initialized. Log file: /Users/lijianxing/lijx-devops/python/fastapi/op-kube-manage-api/logs/fastapi.log,Failed to delete Pod  in namespace dev: 'datetime.datetime' object is not callable
2023-05-11 00:56:42 INFO Logging initialized. Log file: /Users/lijianxing/lijx-devops/python/fastapi/op-kube-manage-api/logs/fastapi.log,Failed to delete Pod  in namespace dev: 'NoneType' object is not subscriptable
2023-05-11 00:57:36 INFO Logging initialized. Log file: /Users/lijianxing/lijx-devops/python/fastapi/op-kube-manage-api/logs/fastapi.log,Failed to delete Pod  in namespace dev: 'NoneType' object is not subscriptable
2023-05-11 00:59:27 INFO Logging initialized. Log file: /Users/lijianxing/lijx-devops/python/fastapi/op-kube-manage-api/logs/fastapi.log,Failed to delete Pod  in namespace dev: 'NoneType' object is not subscriptable
2023-05-11 00:59:28 INFO Logging initialized. Log file: /Users/lijianxing/lijx-devops/python/fastapi/op-kube-manage-api/logs/fastapi.log,Failed to delete Pod  in namespace dev: 'NoneType' object is not subscriptable
2023-05-11 00:59:29 INFO Logging initialized. Log file: /Users/lijianxing/lijx-devops/python/fastapi/op-kube-manage-api/logs/fastapi.log,Failed to delete Pod  in namespace dev: 'NoneType' object is not subscriptable
2023-05-11 00:59:29 INFO Logging initialized. Log file: /Users/lijianxing/lijx-devops/python/fastapi/op-kube-manage-api/logs/fastapi.log,Failed to delete Pod  in namespace dev: 'NoneType' object is not subscriptable
2023-05-11 01:00:12 INFO Logging initialized. Log file: /Users/lijianxing/lijx-devops/python/fastapi/op-kube-manage-api/logs/fastapi.log,Failed to delete Pod  in namespace dev: 'datetime.datetime' object is not callable
2023-05-11 01:00:40 INFO Logging initialized. Log file: /Users/lijianxing/lijx-devops/python/fastapi/op-kube-manage-api/logs/fastapi.log,Failed to delete Pod  in namespace dev: 'datetime.datetime' object is not callable
2023-05-11 01:00:41 INFO Logging initialized. Log file: /Users/lijianxing/lijx-devops/python/fastapi/op-kube-manage-api/logs/fastapi.log,Failed to delete Pod  in namespace dev: 'datetime.datetime' object is not callable
2023-05-11 01:02:17 INFO Logging initialized. Log file: /Users/lijianxing/lijx-devops/python/fastapi/op-kube-manage-api/logs/fastapi.log,Failed to delete Pod  in namespace dev: name 'pod_image' is not defined
2023-05-11 01:02:19 INFO Logging initialized. Log file: /Users/lijianxing/lijx-devops/python/fastapi/op-kube-manage-api/logs/fastapi.log,Failed to delete Pod  in namespace dev: name 'pod_image' is not defined
2023-05-11 01:02:19 INFO Logging initialized. Log file: /Users/lijianxing/lijx-devops/python/fastapi/op-kube-manage-api/logs/fastapi.log,Failed to delete Pod  in namespace dev: name 'pod_image' is not defined
2023-05-11 01:02:34 INFO Logging initialized. Log file: /Users/lijianxing/lijx-devops/python/fastapi/op-kube-manage-api/logs/fastapi.log,Failed to delete Pod  in namespace dev: 'NoneType' object is not subscriptable
2023-05-11 01:03:02 INFO Logging initialized. Log file: /Users/lijianxing/lijx-devops/python/fastapi/op-kube-manage-api/logs/fastapi.log,Failed to delete Pod  in namespace dev: 'NoneType' object is not subscriptable
2023-05-11 01:03:41 INFO Logging initialized. Log file: /Users/lijianxing/lijx-devops/python/fastapi/op-kube-manage-api/logs/fastapi.log,Failed to delete Pod  in namespace dev: 'NoneType' object is not subscriptable
2023-05-11 01:03:41 INFO Logging initialized. Log file: /Users/lijianxing/lijx-devops/python/fastapi/op-kube-manage-api/logs/fastapi.log,Failed to delete Pod  in namespace dev: 'NoneType' object is not subscriptable
2023-05-11 01:03:42 INFO Logging initialized. Log file: /Users/lijianxing/lijx-devops/python/fastapi/op-kube-manage-api/logs/fastapi.log,Failed to delete Pod  in namespace dev: 'NoneType' object is not subscriptable
2023-05-11 01:08:06 INFO Logging initialized. Log file: /Users/lijianxing/lijx-devops/python/fastapi/op-kube-manage-api/logs/fastapi.log,Failed to delete Pod  in namespace dev: 'NoneType' object is not subscriptable
2023-05-11 01:08:07 INFO Logging initialized. Log file: /Users/lijianxing/lijx-devops/python/fastapi/op-kube-manage-api/logs/fastapi.log,Failed to delete Pod  in namespace dev: 'NoneType' object is not subscriptable
2023-05-11 01:08:08 INFO Logging initialized. Log file: /Users/lijianxing/lijx-devops/python/fastapi/op-kube-manage-api/logs/fastapi.log,Failed to delete Pod  in namespace dev: 'NoneType' object is not subscriptable
2023-05-11 01:08:08 INFO Logging initialized. Log file: /Users/lijianxing/lijx-devops/python/fastapi/op-kube-manage-api/logs/fastapi.log,Failed to delete Pod  in namespace dev: 'NoneType' object is not subscriptable
2023-05-11 01:08:09 INFO Logging initialized. Log file: /Users/lijianxing/lijx-devops/python/fastapi/op-kube-manage-api/logs/fastapi.log,Failed to delete Pod  in namespace dev: 'NoneType' object is not subscriptable
2023-05-11 01:08:09 INFO Logging initialized. Log file: /Users/lijianxing/lijx-devops/python/fastapi/op-kube-manage-api/logs/fastapi.log,Failed to delete Pod  in namespace dev: 'NoneType' object is not subscriptable
2023-05-11 01:08:10 INFO Logging initialized. Log file: /Users/lijianxing/lijx-devops/python/fastapi/op-kube-manage-api/logs/fastapi.log,Failed to delete Pod  in namespace dev: 'NoneType' object is not subscriptable
2023-05-11 01:08:11 INFO Logging initialized. Log file: /Users/lijianxing/lijx-devops/python/fastapi/op-kube-manage-api/logs/fastapi.log,Failed to delete Pod  in namespace dev: 'NoneType' object is not subscriptable
2023-05-11 01:18:41 INFO Logging initialized. Log file: /Users/lijianxing/lijx-devops/python/fastapi/op-kube-manage-api/logs/fastapi.log,Failed to delete Pod  in namespace dev: can only concatenate str (not "int") to str
2023-05-11 12:09:57 INFO Logging initialized. Log file: /Users/lijianxing/lijx-devops/python/fastapi/op-kube-manage-api/logs/fastapi.log,Failed to delete Pod  in namespace dev: 'V1ContainerPort' object has no attribute 'get'
2023-05-11 12:09:57 INFO Logging initialized. Log file: /Users/lijianxing/lijx-devops/python/fastapi/op-kube-manage-api/logs/fastapi.log,Failed to delete Pod  in namespace dev: 'V1ContainerPort' object has no attribute 'get'
2023-05-11 12:10:05 INFO Logging initialized. Log file: /Users/lijianxing/lijx-devops/python/fastapi/op-kube-manage-api/logs/fastapi.log,Failed to delete Pod  in namespace dev: 'V1ContainerPort' object has no attribute 'get'
2023-05-11 12:10:23 INFO Logging initialized. Log file: /Users/lijianxing/lijx-devops/python/fastapi/op-kube-manage-api/logs/fastapi.log,Failed to delete Pod  in namespace dev: 'V1ContainerPort' object has no attribute 'get'
2023-05-11 12:10:26 INFO Logging initialized. Log file: /Users/lijianxing/lijx-devops/python/fastapi/op-kube-manage-api/logs/fastapi.log,Failed to delete Pod  in namespace dev: 'V1ContainerPort' object has no attribute 'get'
2023-05-11 12:29:43 INFO Logging initialized. Log file: /Users/lijianxing/lijx-devops/python/fastapi/op-kube-manage-api/logs/fastapi.log,Failed to delete Pod  in namespace kube-system: append() takes exactly one argument (3 given)
2023-05-11 12:29:52 INFO Logging initialized. Log file: /Users/lijianxing/lijx-devops/python/fastapi/op-kube-manage-api/logs/fastapi.log,Failed to delete Pod  in namespace dev: append() takes exactly one argument (3 given)
2023-05-11 12:29:58 INFO Logging initialized. Log file: /Users/lijianxing/lijx-devops/python/fastapi/op-kube-manage-api/logs/fastapi.log,Failed to delete Pod  in namespace dev: append() takes exactly one argument (3 given)
2023-05-11 12:30:04 INFO Logging initialized. Log file: /Users/lijianxing/lijx-devops/python/fastapi/op-kube-manage-api/logs/fastapi.log,Failed to delete Pod  in namespace dev: append() takes exactly one argument (3 given)
2023-05-11 12:59:01 INFO Logging initialized. Log file: /Users/lijianxing/lijx-devops/python/fastapi/op-kube-manage-api/logs/fastapi.log,(pymysql.err.OperationalError) (2003, "Can't connect to MySQL server on 'ops-kube_manage-mysql' ([Errno 61] Connection refused)")
(Background on this error at: https://sqlalche.me/e/14/e3q8)
2023-05-11 12:59:11 INFO Logging initialized. Log file: /Users/lijianxing/lijx-devops/python/fastapi/op-kube-manage-api/logs/fastapi.log,(pymysql.err.OperationalError) (2003, "Can't connect to MySQL server on 'ops-kube_manage-mysql' ([Errno 61] Connection refused)")
(Background on this error at: https://sqlalche.me/e/14/e3q8)
2023-05-11 12:59:45 INFO Logging initialized. Log file: /Users/lijianxing/lijx-devops/python/fastapi/op-kube-manage-api/logs/fastapi.log,(pymysql.err.OperationalError) (2003, "Can't connect to MySQL server on 'ops-kube_manage-mysql' ([Errno 61] Connection refused)")
(Background on this error at: https://sqlalche.me/e/14/e3q8)
2023-05-11 12:59:45 INFO Logging initialized. Log file: /Users/lijianxing/lijx-devops/python/fastapi/op-kube-manage-api/logs/fastapi.log,(pymysql.err.OperationalError) (2003, "Can't connect to MySQL server on 'ops-kube_manage-mysql' ([Errno 61] Connection refused)")
(Background on this error at: https://sqlalche.me/e/14/e3q8)
2023-05-11 12:59:45 INFO Logging initialized. Log file: /Users/lijianxing/lijx-devops/python/fastapi/op-kube-manage-api/logs/fastapi.log,(pymysql.err.OperationalError) (2003, "Can't connect to MySQL server on 'ops-kube_manage-mysql' ([Errno 61] Connection refused)")
(Background on this error at: https://sqlalche.me/e/14/e3q8)
2023-05-11 12:59:45 INFO Logging initialized. Log file: /Users/lijianxing/lijx-devops/python/fastapi/op-kube-manage-api/logs/fastapi.log,(pymysql.err.OperationalError) (2003, "Can't connect to MySQL server on 'ops-kube_manage-mysql' ([Errno 61] Connection refused)")
(Background on this error at: https://sqlalche.me/e/14/e3q8)
2023-05-11 12:59:45 INFO Logging initialized. Log file: /Users/lijianxing/lijx-devops/python/fastapi/op-kube-manage-api/logs/fastapi.log,(pymysql.err.OperationalError) (2003, "Can't connect to MySQL server on 'ops-kube_manage-mysql' ([Errno 61] Connection refused)")
(Background on this error at: https://sqlalche.me/e/14/e3q8)
2023-05-11 12:59:45 INFO Logging initialized. Log file: /Users/lijianxing/lijx-devops/python/fastapi/op-kube-manage-api/logs/fastapi.log,(pymysql.err.OperationalError) (2003, "Can't connect to MySQL server on 'ops-kube_manage-mysql' ([Errno 61] Connection refused)")
(Background on this error at: https://sqlalche.me/e/14/e3q8)
