2023-04-27 11:23:28 INFO Logging initialized. Log file: ./logs/fastapi.log,startup fastapi
2023-04-27 11:23:49 INFO Logging initialized. Log file: ./logs/fastapi.log,startup fastapi
2023-04-27 11:23:59 INFO Logging initialized. Log file: ./logs/fastapi.log,startup fastapi
2023-04-27 15:17:55 INFO Logging initialized. Log file: ./logs/fastapi.log,startup fastapi
2023-04-27 15:49:30 INFO Logging initialized. Log file: ./logs/fastapi.log,startup fastapi
2023-04-27 15:50:13 INFO Logging initialized. Log file: ./logs/fastapi.log,startup fastapi
2023-05-07 23:21:22 INFO Logging initialized. Log file: ./logs/fastapi.log,startup fastapi
2023-05-08 22:04:55 INFO Logging initialized. Log file: ./logs/fastapi.log,startup fastapi
2023-05-08 22:05:32 INFO Logging initialized. Log file: ./logs/fastapi.log,startup fastapi
2023-05-08 22:05:39 INFO Logging initialized. Log file: ./logs/fastapi.log,startup fastapi
2023-05-08 22:05:53 INFO Logging initialized. Log file: ./logs/fastapi.log,startup fastapi
2023-05-08 22:06:11 INFO Logging initialized. Log file: ./logs/fastapi.log,startup fastapi
2023-05-08 22:10:30 INFO Logging initialized. Log file: ./logs/fastapi.log,startup fastapi
2023-05-08 23:45:20 INFO Logging initialized. Log file: /Users/lijianxing/lijx-devops/python/fastapi/op-kube-manage-api/logs/fastapi.log,(pymysql.err.OperationalError) (2003, "Can't connect to MySQL server on 'ops-kube_manage-mysql' ([Errno 8] nodename nor servname provided, or not known)")
(Background on this error at: https://sqlalche.me/e/14/e3q8)
2023-05-08 23:45:22 INFO Logging initialized. Log file: /Users/lijianxing/lijx-devops/python/fastapi/op-kube-manage-api/logs/fastapi.log,(pymysql.err.OperationalError) (2003, "Can't connect to MySQL server on 'ops-kube_manage-mysql' ([Errno 8] nodename nor servname provided, or not known)")
(Background on this error at: https://sqlalche.me/e/14/e3q8)
2023-05-08 23:45:22 INFO Logging initialized. Log file: /Users/lijianxing/lijx-devops/python/fastapi/op-kube-manage-api/logs/fastapi.log,(pymysql.err.OperationalError) (2003, "Can't connect to MySQL server on 'ops-kube_manage-mysql' ([Errno 8] nodename nor servname provided, or not known)")
(Background on this error at: https://sqlalche.me/e/14/e3q8)
2023-05-08 23:45:22 INFO Logging initialized. Log file: /Users/lijianxing/lijx-devops/python/fastapi/op-kube-manage-api/logs/fastapi.log,(pymysql.err.OperationalError) (2003, "Can't connect to MySQL server on 'ops-kube_manage-mysql' ([Errno 8] nodename nor servname provided, or not known)")
(Background on this error at: https://sqlalche.me/e/14/e3q8)
2023-05-08 23:45:22 INFO Logging initialized. Log file: /Users/lijianxing/lijx-devops/python/fastapi/op-kube-manage-api/logs/fastapi.log,(pymysql.err.OperationalError) (2003, "Can't connect to MySQL server on 'ops-kube_manage-mysql' ([Errno 8] nodename nor servname provided, or not known)")
(Background on this error at: https://sqlalche.me/e/14/e3q8)
2023-05-08 23:45:23 INFO Logging initialized. Log file: /Users/lijianxing/lijx-devops/python/fastapi/op-kube-manage-api/logs/fastapi.log,(pymysql.err.OperationalError) (2003, "Can't connect to MySQL server on 'ops-kube_manage-mysql' ([Errno 8] nodename nor servname provided, or not known)")
(Background on this error at: https://sqlalche.me/e/14/e3q8)
2023-05-08 23:45:23 INFO Logging initialized. Log file: /Users/lijianxing/lijx-devops/python/fastapi/op-kube-manage-api/logs/fastapi.log,(pymysql.err.OperationalError) (2003, "Can't connect to MySQL server on 'ops-kube_manage-mysql' ([Errno 8] nodename nor servname provided, or not known)")
(Background on this error at: https://sqlalche.me/e/14/e3q8)
2023-05-08 23:45:23 INFO Logging initialized. Log file: /Users/lijianxing/lijx-devops/python/fastapi/op-kube-manage-api/logs/fastapi.log,(pymysql.err.OperationalError) (2003, "Can't connect to MySQL server on 'ops-kube_manage-mysql' ([Errno 8] nodename nor servname provided, or not known)")
(Background on this error at: https://sqlalche.me/e/14/e3q8)
2023-05-08 23:45:23 INFO Logging initialized. Log file: /Users/lijianxing/lijx-devops/python/fastapi/op-kube-manage-api/logs/fastapi.log,(pymysql.err.OperationalError) (2003, "Can't connect to MySQL server on 'ops-kube_manage-mysql' ([Errno 8] nodename nor servname provided, or not known)")
(Background on this error at: https://sqlalche.me/e/14/e3q8)
2023-05-08 23:45:24 INFO Logging initialized. Log file: /Users/lijianxing/lijx-devops/python/fastapi/op-kube-manage-api/logs/fastapi.log,(pymysql.err.OperationalError) (2003, "Can't connect to MySQL server on 'ops-kube_manage-mysql' ([Errno 8] nodename nor servname provided, or not known)")
(Background on this error at: https://sqlalche.me/e/14/e3q8)
2023-05-08 23:45:24 INFO Logging initialized. Log file: /Users/lijianxing/lijx-devops/python/fastapi/op-kube-manage-api/logs/fastapi.log,(pymysql.err.OperationalError) (2003, "Can't connect to MySQL server on 'ops-kube_manage-mysql' ([Errno 8] nodename nor servname provided, or not known)")
(Background on this error at: https://sqlalche.me/e/14/e3q8)
2023-05-08 23:45:24 INFO Logging initialized. Log file: /Users/lijianxing/lijx-devops/python/fastapi/op-kube-manage-api/logs/fastapi.log,(pymysql.err.OperationalError) (2003, "Can't connect to MySQL server on 'ops-kube_manage-mysql' ([Errno 8] nodename nor servname provided, or not known)")
(Background on this error at: https://sqlalche.me/e/14/e3q8)
2023-05-08 23:45:24 INFO Logging initialized. Log file: /Users/lijianxing/lijx-devops/python/fastapi/op-kube-manage-api/logs/fastapi.log,(pymysql.err.OperationalError) (2003, "Can't connect to MySQL server on 'ops-kube_manage-mysql' ([Errno 8] nodename nor servname provided, or not known)")
(Background on this error at: https://sqlalche.me/e/14/e3q8)
2023-05-08 23:45:24 INFO Logging initialized. Log file: /Users/lijianxing/lijx-devops/python/fastapi/op-kube-manage-api/logs/fastapi.log,(pymysql.err.OperationalError) (2003, "Can't connect to MySQL server on 'ops-kube_manage-mysql' ([Errno 8] nodename nor servname provided, or not known)")
(Background on this error at: https://sqlalche.me/e/14/e3q8)
2023-05-08 23:45:24 INFO Logging initialized. Log file: /Users/lijianxing/lijx-devops/python/fastapi/op-kube-manage-api/logs/fastapi.log,(pymysql.err.OperationalError) (2003, "Can't connect to MySQL server on 'ops-kube_manage-mysql' ([Errno 8] nodename nor servname provided, or not known)")
(Background on this error at: https://sqlalche.me/e/14/e3q8)
2023-05-08 23:45:26 INFO Logging initialized. Log file: /Users/lijianxing/lijx-devops/python/fastapi/op-kube-manage-api/logs/fastapi.log,(pymysql.err.OperationalError) (2003, "Can't connect to MySQL server on 'ops-kube_manage-mysql' ([Errno 8] nodename nor servname provided, or not known)")
(Background on this error at: https://sqlalche.me/e/14/e3q8)
2023-05-08 23:45:26 INFO Logging initialized. Log file: /Users/lijianxing/lijx-devops/python/fastapi/op-kube-manage-api/logs/fastapi.log,(pymysql.err.OperationalError) (2003, "Can't connect to MySQL server on 'ops-kube_manage-mysql' ([Errno 8] nodename nor servname provided, or not known)")
(Background on this error at: https://sqlalche.me/e/14/e3q8)
2023-05-08 23:45:26 INFO Logging initialized. Log file: /Users/lijianxing/lijx-devops/python/fastapi/op-kube-manage-api/logs/fastapi.log,(pymysql.err.OperationalError) (2003, "Can't connect to MySQL server on 'ops-kube_manage-mysql' ([Errno 8] nodename nor servname provided, or not known)")
(Background on this error at: https://sqlalche.me/e/14/e3q8)
2023-05-08 23:45:26 INFO Logging initialized. Log file: /Users/lijianxing/lijx-devops/python/fastapi/op-kube-manage-api/logs/fastapi.log,(pymysql.err.OperationalError) (2003, "Can't connect to MySQL server on 'ops-kube_manage-mysql' ([Errno 8] nodename nor servname provided, or not known)")
(Background on this error at: https://sqlalche.me/e/14/e3q8)
2023-05-08 23:45:28 INFO Logging initialized. Log file: /Users/lijianxing/lijx-devops/python/fastapi/op-kube-manage-api/logs/fastapi.log,(pymysql.err.OperationalError) (2003, "Can't connect to MySQL server on 'ops-kube_manage-mysql' ([Errno 8] nodename nor servname provided, or not known)")
(Background on this error at: https://sqlalche.me/e/14/e3q8)
2023-05-08 23:45:28 INFO Logging initialized. Log file: /Users/lijianxing/lijx-devops/python/fastapi/op-kube-manage-api/logs/fastapi.log,(pymysql.err.OperationalError) (2003, "Can't connect to MySQL server on 'ops-kube_manage-mysql' ([Errno 8] nodename nor servname provided, or not known)")
(Background on this error at: https://sqlalche.me/e/14/e3q8)
2023-05-08 23:45:28 INFO Logging initialized. Log file: /Users/lijianxing/lijx-devops/python/fastapi/op-kube-manage-api/logs/fastapi.log,(pymysql.err.OperationalError) (2003, "Can't connect to MySQL server on 'ops-kube_manage-mysql' ([Errno 8] nodename nor servname provided, or not known)")
(Background on this error at: https://sqlalche.me/e/14/e3q8)
2023-05-08 23:45:28 INFO Logging initialized. Log file: /Users/lijianxing/lijx-devops/python/fastapi/op-kube-manage-api/logs/fastapi.log,(pymysql.err.OperationalError) (2003, "Can't connect to MySQL server on 'ops-kube_manage-mysql' ([Errno 8] nodename nor servname provided, or not known)")
(Background on this error at: https://sqlalche.me/e/14/e3q8)
